<?xml version="1.0" ?>
<mujoco model="kinova3_6dof">
  <compiler angle="radian"/>
  <actuator>
      <motor ctrllimited="true"  ctrlrange="-39.0 39.0" joint="joint_1" name="torq_j1" />
      <motor ctrllimited="true"  ctrlrange="-39.0 39.0" joint="joint_2" name="torq_j2" />
      <motor ctrllimited="true"  ctrlrange="-39.0 39.0" joint="joint_3" name="torq_j3" />
      <motor ctrllimited="true"  ctrlrange="-09.0 09.0" joint="joint_4" name="torq_j4" />
      <motor ctrllimited="true"  ctrlrange="-09.0 09.0" joint="joint_5" name="torq_j5" />
      <motor ctrllimited="true"  ctrlrange="-09.0 09.0" joint="joint_6" name="torq_j6" />
  </actuator>
  <asset>
    <mesh name="base_link" file="meshes/base_link.STL"/>
    <mesh name="shoulder_link" file="meshes/shoulder_link.STL"/>
    <mesh name="bicep_link" file="meshes/bicep_link.STL"/>
    <mesh name="forearm_link" file="meshes/forearm_link.STL"/>
    <mesh name="spherical_wrist_1_link" file="meshes/spherical_wrist_1_link.STL"/>
    <mesh name="spherical_wrist_2_link" file="meshes/spherical_wrist_2_link.STL"/>
    <mesh name="bracelet_with_vision_link" file="meshes/bracelet_with_vision_link.STL"/>
  </asset>

  <worldbody>
    <body name="base" pos="0 0 0">
      <camera mode="fixed" name="robotview" pos="1.0 0 0.4" quat="0.653 0.271 0.271 0.653"/>
      <inertial diaginertia="0 0 0" mass="0" pos="0 0 0"/>
      
      <body name="fixed_base_link" pos="0 0 0">
        <site name="right_center" pos="0 0 0" size="0.01" rgba="1 0.3 0.3 1" group="2"/>
        <geom type="mesh" contype="0" conaffinity="0" group="1" rgba="1 1 1 1" mesh="base_link"/>
        <geom type="mesh" conaffinity="0" rgba="0.75294 0.75294 0.75294 1" mesh="base_link" name="base_collision"/>

        <body name="shoulder_link" pos="0 0 0.15643" quat="-3.67321e-06 -1 0 0">
          <inertial pos="-2.3e-05 -0.010364 -0.07336" quat="0.707051 0.0451246 -0.0453544 0.704263" mass="1.377" diaginertia="0.00488868 0.00457 0.00135132"/>
          <joint name="joint_1" pos="0 0 0" axis="0 0 1" damping="0.01"/>
          <geom name="shoulder_link_visual" type="mesh" contype="0" conaffinity="0" group="1" density="0" rgba="0.75294 0.75294 0.75294 1" mesh="shoulder_link"/>
          <geom name="shoulder_link_collision" type="mesh" rgba="0.75294 0.75294 0.75294 1" mesh="shoulder_link"/>
          <body name="bicep_link" pos="0 0.005375 -0.12838" quat="0.707105 0.707108 0 0">
            <inertial pos="3.5e-05 -0.208207 -0.01889" quat="0.499531 0.50049 -0.500566 0.499411" mass="1.262" diaginertia="0.0471882 0.046752 0.000849791"/>
            <joint name="joint_2" pos="0 0 0" axis="0 0 1" limited="true" range="-2.25 2.25" armature="0" frictionloss="0" damping="0"/>
            <geom name="bicep_link_visual" type="mesh" contype="0" conaffinity="0" group="1" density="0" rgba="0.75294 0.75294 0.75294 1" mesh="bicep_link"/>
            <geom name="bicep_link_collision" type="mesh" rgba="0.75294 0.75294 0.75294 1" mesh="bicep_link"/>
            <body name="forearm_link" pos="0 -0.41 0" quat="-3.67321e-06 1 0 0">
              <inertial pos="1.8e-05 0.076168 -0.01397" quat="0.513497 0.485985 -0.486188 0.513577" mass="0.93" diaginertia="0.00848774 0.008292 0.000604256"/>
              <joint name="joint_3" pos="0 0 0" axis="0 0 1" limited="true" range="-2.58 2.58" armature="0" frictionloss="0" damping="0"/>
              <geom name="forearm_link_visual" type="mesh" contype="0" conaffinity="0" group="1" density="0" rgba="0.75294 0.75294 0.75294 1" mesh="forearm_link"/>
              <geom name="forearm_link_collision" type="mesh" rgba="0.75294 0.75294 0.75294 1" mesh="forearm_link"/>
              <body name="spherical_wrist_1_link" pos="0 0.20843 -0.006375" quat="0.707105 0.707108 0 0">
                <inertial pos="-1e-06 0.008486 -0.062937" quat="0.704382 -0.062019 0.062019 0.704382" mass="0.6781" diaginertia="0.00170753 0.001645 0.000347472"/>
                <joint name="joint_4" pos="0 0 0" axis="0 0 1" armature="0" frictionloss="0" damping="0"/>
                <geom name="spherical_wrist_1_link_visual" type="mesh" contype="0" conaffinity="0" group="1" density="0" rgba="0.75294 0.75294 0.75294 1" mesh="spherical_wrist_1_link"/>
                <geom name="spherical_wrist_1_link_collision" type="mesh" rgba="0.75294 0.75294 0.75294 1" mesh="spherical_wrist_1_link"/>
                <body name="spherical_wrist_2_link" pos="0 -0.00017505 -0.10593" quat="0.707105 -0.707108 0 0">
                  <inertial pos="-1e-06 0.046429 -0.008704" quat="0.5446 0.451011 -0.451011 0.5446" mass="0.678" diaginertia="0.00174437 0.001685 0.000351632"/>
                  <joint name="joint_5" pos="0 0 0" axis="0 0 1" limited="true" range="-2.10 2.10" armature="0" frictionloss="0" damping="0"/>
                  <geom name="spherical_wrist_2_link_visual" type="mesh" contype="0" conaffinity="0" group="1" density="0" rgba="0.75294 0.75294 0.75294 1" mesh="spherical_wrist_2_link"/>
                  <geom name="spherical_wrist_2_link_collision" type="mesh" rgba="0.75294 0.75294 0.75294 1" mesh="spherical_wrist_2_link"/>
                  <body name="bracelet_link" pos="0 0.10593 -0.00017505" quat="0.707105 0.707108 0 0">
                    <inertial pos="0.000281 0.011402 -0.029798" quat="0.394358 0.596779 -0.577293 0.393789" mass="0.5" diaginertia="0.000657336 0.000587019 0.000320645"/>
                    <joint name="joint_6" pos="0 0 0" axis="0 0 1" armature="0" frictionloss="0" damping="0"/>
                    <geom name="bracelet_with_vision_link_visual" type="mesh" contype="0" conaffinity="0" group="1" density="0" rgba="0.75294 0.75294 0.75294 1" mesh="bracelet_with_vision_link"/>
                    <geom name="bracelet_with_vision_link_collision" type="mesh" rgba="0.75294 0.75294 0.75294 1" mesh="bracelet_with_vision_link"/>
                    <body name="right_hand" pos="0 0 -0.0615" quat="0 0.707105 -0.707108 0">
                        <site name="ee" pos="0 0 0" size="0.01 0.01 0.01" rgba="0 0 1 1" type="sphere" group="1"/>
                        <site name="ee_x" pos="0 0 0" size="0.005 .1" quat="0.707105 0.707108 0 0" rgba="1 0 0 0" type="cylinder" group="1"/>
                        <site name="ee_z" pos="0 0 0" size="0.005 .1" quat="0.707105 0 0 0.707108" rgba="0 0 1 0" type="cylinder" group="1"/>
                        <site name="ee_y" pos="0 0 0" size="0.005 .1" quat="0.707105 0 0.707108 0" rgba="0 1 0 0" type="cylinder" group="1"/>
                        <camera mode="fixed" name="eye_in_hand" pos="0.05 0 0" quat="0 0.707108 0.707108 0" fovy="75"/>
                    </body>
                  </body>
                </body>
              </body>
            </body>
          </body>
        </body>
      </body>
    </body>
  </worldbody>
</mujoco>

